Workbook

Sheet Dashboard
A1: SonarQube Dashboard (sample) - aggregated from service sheets
A3: Services Overview
A4: Service | B4: Project Key | C4: LOC | D4: Lines to Cover | E4: Covered Lines | F4: Coverage % (weighted) | G4: Bugs | H4: Vulnerabilities | I4: Code Smells | J4: Hotspots | K4: Hotspots Reviewed % | L4: Duplications % | M4: Last analysis | N4: Notes | O4: Reviewed Hotspots | P4: Total Hotspots
A5: =template!B3 -> svc-auth | B5: =template!B4 -> pn2-auth-service | C5: =template!B16 -> 9500 | D5: =template!B17 -> 2800 | E5: =template!B18 -> 820 | F5: =IF(D5=0,0,E5/D5) -> 0.29285714 | G5: =template!B9 -> 10 | H5: =template!B10 -> 0 | I5: =template!B11 -> 14 | J5: =template!B12 -> 4 | K5: =template!B13 -> 0 | L5: =template!B15 -> 0.013 | M5: =template!B19 -> 46038.34 | N5: Sample data | O5: =ROUND(J5*K5,0) -> 0 | P5: =J5 -> 4
A6: =#REF! -> #REF! | B6: =#REF! -> #REF! | C6: =#REF! -> #REF! | D6: =#REF! -> #REF! | E6: =#REF! -> #REF! | F6: =IF(D6=0,0,E6/D6) -> #REF! | G6: =#REF! -> #REF! | H6: =#REF! -> #REF! | I6: =#REF! -> #REF! | J6: =#REF! -> #REF! | K6: =#REF! -> #REF! | L6: =#REF! -> #REF! | M6: =#REF! -> #REF! | N6: Sample data | O6: =ROUND(J6*K6,0) -> #REF! | P6: =J6 -> #REF!
A7: =#REF! -> #REF! | B7: =#REF! -> #REF! | C7: =#REF! -> #REF! | D7: =#REF! -> #REF! | E7: =#REF! -> #REF! | F7: =IF(D7=0,0,E7/D7) -> #REF! | G7: =#REF! -> #REF! | H7: =#REF! -> #REF! | I7: =#REF! -> #REF! | J7: =#REF! -> #REF! | K7: =#REF! -> #REF! | L7: =#REF! -> #REF! | M7: =#REF! -> #REF! | N7: Sample data | O7: =ROUND(J7*K7,0) -> #REF! | P7: =J7 -> #REF!
A8: Key KPIs | G8: =#REF! -> #REF! | H8: =#REF! -> #REF! | I8: =#REF! -> #REF! | J8: =#REF! -> #REF! | K8: =#REF! -> #REF! | L8: =#REF! -> #REF! | M8: =#REF! -> #REF! | N8: Sample data | O8: =ROUND(J8*K8,0) -> #REF! | P8: =J8 -> #REF!
A9: Total Bugs | B9: =G9 -> #REF! | C9: =SUM(C5:C8) -> #REF! | D9: =SUM(D5:D8) -> #REF! | E9: =SUM(E5:E8) -> #REF! | F9: =IF(D9=0,0,E9/D9) -> #REF! | G9: =SUM(G5:G8) -> #REF! | H9: =SUM(H5:H8) -> #REF! | I9: =SUM(I5:I8) -> #REF! | J9: =SUM(J5:J8) -> #REF! | K9: =IF(P9=0,1,O9/P9) -> #REF! | L9: =AVERAGE(L5:L8) -> #REF! | M9: - | O9: =SUM(O5:O8) -> #REF! | P9: =SUM(P5:P8) -> #REF!
A10: Total Vulnerabilities | B10: =H9 -> #REF!
A11: Overall Coverage (weighted) | B11: =F9 -> #REF!
A12: Hotspots Reviewed % (weighted) | B12: =K9 -> #REF!
A14: Charts (sample)

Sheet README
A1: SonarQube -> Excel Export Template (for DEV implementation)
A3: Mục tiêu:
A4: - Workbook này là template để DEV export dữ liệu từ SonarQube Web API vào Excel.
A5: - Mỗi service/client là 1 sheet riêng, và 1 sheet 'Dashboard' tổng hợp.
A7: Nguyên tắc thiết kế (security-first):
A8: - Tool export nên chạy bên ngoài SonarQube server (không cài plugin), dùng token quyền tối thiểu (read-only).
A10: Cấu trúc mỗi service sheet:
A11: 1) Metadata (Service Name, Project Key, Branch, Last analysis)
A12: 2) Dashboard Feed (block cố định để Dashboard đọc, KHÔNG đổi vị trí ô)
A13: 3) Issue List (bảng dạng Table để filter/sort)
A15: Gợi ý API (tham khảo):
A16: - Measures: /api/measures/component?component=<projectKey>&metricKeys=...
... A26: Sheet Dashboard đã có công thức + biểu đồ minh hoạ dựa trên các ô 'Dashboard Feed' của từng service.

Sheet template
A1: Service Report - svc-auth
A3: Service Name | B3: svc-auth
A4: Project Key | B4: pn2-auth-service
A5: Branch | B5: main
A6: Last analysis | B6: 46038.34
A8: Dashboard Feed (DO NOT MOVE THESE CELLS)
A9: Bugs | B9: =COUNTIF(B24:B51,"BUG") -> 10
A10: Vulnerabilities | B10: =COUNTIF(B24:B51,"VULNERABILITY") -> 0
A11: Code Smells | B11: =COUNTIF(B24:B51,"CODE_SMELL") -> 14
A12: Security Hotspots | B12: =COUNTIF(B24:B51,"SECURITY_HOTSPOT") -> 4 | C12: Reviewed hotspots (SAFE+FIX) | D12: =COUNTIF(K24:K51,"SAFE")+COUNTIF(K24:K51,"FIX") -> 0
A13: Hotspots Reviewed % | B13: =IF(B12=0,1,D12/B12) -> 0
A14: Coverage % | B14: =IF(B17=0,0,B18/B17) -> 0.29285714
A15: Duplications % | B15: 0.013
A16: Lines of Code | B16: 9500
A17: Lines to Cover | B17: 2800
A18: Covered Lines | B18: 820
A19: Last analysis | B19: 46038.34
A22: Issues (sample data) - DEV will replace with exported data
A23: Issue Key | B23: Type | C23: Severity | D23: Status | E23: Rule | F23: Component | G23: Line | H23: Message | I23: Effort (min) | J23: Tags | K23: Hotspot Review | L23: Created | M23: Updated | N23: Author
A24: SVC-AUTH-1000 | B24: BUG | C24: CRITICAL | D24: OPEN | E24: java:S2259 | F24: src/main/java/com/company/svc-auth/controller | G24: 204 | H24: Possible NullPointerException; add null-check or Optional | I24: 5 | J24: db | L24: 46027.708 | M24: 46037.917 | N24: binh.tran
A25: SVC-AUTH-1001 | B25: CODE_SMELL | C25: MINOR | D25: OPEN | E25: java:S1192 | F25: src/main/java/com/company/svc-auth/controller | G25: 315 | H25: Refactor method to reduce cognitive complexity | I25: 90 | J25: performance | L25: 46017.083 | M25: 46017.292 | N25: an.nguyen
A26: SVC-AUTH-1002 | B26: CODE_SMELL | C26: CRITICAL | D26: RESOLVED | E26: java:S1192 | F26: src/main/java/com/company/svc-auth/config | G26: 303 | H26: Refactor method to reduce cognitive complexity | I26: 30 | J26: api,auth,performance | L26: 46023.333 | M26: 46038.333 | N26: chi.le
A27: SVC-AUTH-1003 | B27: CODE_SMELL | C27: MAJOR | D27: RESOLVED | E27: java:S106 | F27: src/main/java/com/company/svc-auth/config | G27: 403 | H27: Refactor method to reduce cognitive complexity | I27: 60 | J27: db,logging,security | L27: 46025.542 | M27: 46040.875 | N27: chi.le
A28: SVC-AUTH-1004 | B28: BUG | C28: MINOR | D28: RESOLVED | E28: java:S2095 | F28: src/main/java/com/company/svc-auth/repository | G28: 97 | H28: Possible NullPointerException; add null-check or Optional | I28: 90 | J28: db,performance,security | L28: 46014.417 | M28: 46026.458 | N28: duong.pham
A29: SVC-AUTH-1005 | B29: CODE_SMELL | C29: MINOR | D29: OPEN | E29: java:S1192 | F29: src/main/java/com/company/svc-auth/service | G29: 217 | H29: Refactor method to reduce cognitive complexity | I29: 90 | J29: auth,logging,performance | L29: 46027.667 | M29: 46028.833 | N29: binh.tran
A30: SVC-AUTH-1006 | B30: SECURITY_HOTSPOT | C30: MAJOR | D30: RESOLVED | E30: java:S5144 | F30: src/main/java/com/company/svc-auth/controller | G30: 78 | H30: Review use of sensitive method; validate input and access control | I30: 45 | J30: logging,security | K30: TO_REVIEW | L30: 46022.25 | M30: 46022.417 | N30: chi.le
A31: SVC-AUTH-1007 | B31: BUG | C31: MAJOR | D31: OPEN | E31: java:S2142 | F31: src/main/java/com/company/svc-auth/controller | G31: 417 | H31: Possible NullPointerException; add null-check or Optional | I31: 60 | J31: api,cleanup | L31: 46027.5 | M31: 46029.833 | N31: an.nguyen
A32: SVC-AUTH-1008 | B32: BUG | C32: MAJOR | D32: OPEN | E32: java:S2259 | F32: src/main/java/com/company/svc-auth/service | G32: 224 | H32: Possible NullPointerException; add null-check or Optional | I32: 20 | J32: api,logging,security | L32: 45997.917 | M32: 46002.125 | N32: an.nguyen
A33: SVC-AUTH-1009 | B33: CODE_SMELL | C33: MAJOR | D33: RESOLVED | E33: java:S1192 | F33: src/main/java/com/company/svc-auth/config | G33: 198 | H33: Refactor method to reduce cognitive complexity | I33: 10 | J33: cleanup,logging,security | L33: 46001.708 | M33: 46012.042 | N33: binh.tran
A34: SVC-AUTH-1010 | B34: CODE_SMELL | C34: MAJOR | D34: OPEN | E34: java:S1192 | F34: src/main/java/com/company/svc-auth/config | G34: 165 | H34: Refactor method to reduce cognitive complexity | I34: 45 | J34: api,auth,bugfix | L34: 46020 | M34: 46025.333 | N34: ha.ngo
A35: SVC-AUTH-1011 | B35: BUG | C35: MINOR | D35: OPEN | E35: java:S2095 | F35: src/main/java/com/company/svc-auth/repository | G35: 57 | H35: Possible NullPointerException; add null-check or Optional | I35: 45 | J35: api,security | L35: 46010.667 | M35: 46017.792 | N35: chi.le
A36: SVC-AUTH-1012 | B36: BUG | C36: MAJOR | D36: OPEN | E36: java:S2259 | F36: src/main/java/com/company/svc-auth/service | G36: 147 | H36: Possible NullPointerException; add null-check or Optional | I36: 10 | J36: api,bugfix,logging | L36: 46029.292 | M36: 46031.5 | N36: chi.le
A37: SVC-AUTH-1013 | B37: BUG | C37: INFO | D37: OPEN | E37: java:S2142 | F37: src/main/java/com/company/svc-auth/controller | G37: 141 | H37: Possible NullPointerException; add null-check or Optional | I37: 20 | J37: security | L37: 46029.625 | M37: 46039.875 | N37: ha.ngo
A38: SVC-AUTH-1014 | B38: CODE_SMELL | C38: MINOR | D38: CONFIRMED | E38: java:S1192 | F38: src/main/java/com/company/svc-auth/repository | G38: 366 | H38: Refactor method to reduce cognitive complexity | I38: 90 | J38: auth,bugfix,logging | L38: 46030.125 | M38: 46031.333 | N38: chi.le
A39: SVC-AUTH-1015 | B39: BUG | C39: MAJOR | D39: RESOLVED | E39: java:S2259 | F39: src/main/java/com/company/svc-auth/service | G39: 205 | H39: Possible NullPointerException; add null-check or Optional | I39: 30 | J39: bugfix,logging,security | L39: 45996.542 | M39: 46008.875 | N39: binh.tran
A40: SVC-AUTH-1016 | B40: SECURITY_HOTSPOT | C40: CRITICAL | D40: OPEN | E40: java:S4502 | F40: src/main/java/com/company/svc-auth/repository | G40: 38 | H40: Review use of sensitive method; validate input and access control | I40: 10 | J40: auth,db,performance | K40: TO_REVIEW | L40: 46017.042 | M40: 46029.208 | N40: duong.pham
A41: SVC-AUTH-1017 | B41: CODE_SMELL | C41: MAJOR | D41: OPEN | E41: java:S3776 | F41: src/main/java/com/company/svc-auth/config | G41: 266 | H41: Refactor method to reduce cognitive complexity | I41: 15 | J41: logging | L41: 46029.333 | M41: 46039.333 | N41: an.nguyen
A42: SVC-AUTH-1018 | B42: CODE_SMELL | C42: MINOR | D42: OPEN | E42: java:S106 | F42: src/main/java/com/company/svc-auth/config | G42: 287 | H42: Refactor method to reduce cognitive complexity | I42: 5 | J42: api,auth,db | L42: 46002.417 | M42: 46013.542 | N42: duong.pham
A43: SVC-AUTH-1019 | B43: SECURITY_HOTSPOT | C43: BLOCKER | D43: REOPENED | E43: java:S5144 | F43: src/main/java/com/company/svc-auth/controller | G43: 139 | H43: Review use of sensitive method; validate input and access control | I43: 60 | J43: cleanup,db,security | K43: TO_REVIEW | L43: 46011.208 | M43: 46024.417 | N43: an.nguyen
A44: SVC-AUTH-1020 | B44: BUG | C44: MAJOR | D44: RESOLVED | E44: java:S2095 | F44: src/main/java/com/company/svc-auth/service | G44: 165 | H44: Possible NullPointerException; add null-check or Optional | I44: 120 | J44: auth | L44: 46024.583 | M44: 46031.75 | N44: an.nguyen
...
